Workbook

Sheet Summary
A1: MID-CYCLE ALIGNMENT ANALYSIS — Spring 2026 Tomatoes Cycle
A2: Cycle CYC-20260621-30BC · Round 1 (run 1) · Analysis v1 · sealed 2026-06-21 18:53
A3: ALIGNMENT / COMPARISON tool (D26) — what the team works through to DECIDE, not a final summary.
A4: Generated 2026-06-21 · LIVE CYCLE DATA — real names & prices · DECISION-SUPPORT — recommends, does not assert
A6: Item | B6: Value
A7: Cycle | B7: CYC-20260621-30BC — Spring 2026 Tomatoes Cycle
A8: Scope | B8: 2 DCs × 2 lots × 1 timeframes; 2 invited suppliers
A9: Strategy | B9: balanced preset · weights P0.31/Cov0.22/Hist0.18/Z0.09/Cont0.20 · max 2 suppliers/DC
A10: Headline (A vs B) | B10: Recommendation = Scenario B (Risk-adjusted recommendation): $218,400 spend, 22.2% vs baseline, 0.0% above the Scenario A lowest-cost benchmark ($218,400) — the risk-adjusted premium for coverage/continuity.
A11: How to use this workbook | B11: Supplier Comparison = every supplier per cell side by side (the price debate). Scenario Comparison = the lenses side by side (which lens). Custom Scenario = override per cell, watch spend/savings recompute live.
A13: Headline KPIs — the four lenses (cost · hidden cost · relationships · negotiation)
A14: Cost & savings — Savings vs incumbent | B14: $62,400
A15: Cost & savings — Savings % | B15: 22.2%
A16: Hidden costs — Avg transit (days) | B16: 0.0
A17: Hidden costs — Freshness watches | B17: 0
A18: Relationships — Preserved / Created | B18: 1 / 1
A19: Negotiation — Incumbent vs field move | B19: 0.0% / 0.0% (in line)
A21: What's in this workbook (where to go)
A22: Tab | B22: Answers the question
A23: Controls | B23: How was this run? Horizon, scope, baselines, engine weights & rules.
A24: § DECIDE — cost & savings
A25: Award Summary | B25: The recommendation: per-DC incumbent→recommended + savings $ to sign.
A26: Scenario Comparison | B26: Which lens? A-G + LIVE Custom side by side, drill to DC.
A27: Lowest-Cost Check | B27: Is the rec the cheapest? If not, the premium it trades.
A28: § COMPARE SUPPLIERS
A29: Supplier Comparison | B29: Which supplier per cell? Every eligible supplier's $/case.
A30: Landed & Hidden Costs | B30: Beyond price: freight + transit/freshness — the true cost.
A31: § RELATIONSHIPS & NEGOTIATION
A32: Share & Relationships | B32: Who carries the business — preserve vs create + dependency.
A33: Incumbent Retention | B33: What keeping each incumbent costs vs the rec.
A34: Negotiation Dynamics | B34: Treated fairly? Concession vs the field, real risk vs theater.
A35: § DILIGENCE
A36: Coverage | B36: Can they supply it? Offered vs required volume + cover band.
A37: Detailed Scoring | B37: Why these scores? The 5 factors + the market stats behind them.
A38: Data Quality | B38: What's missing/thin? No-bids, thin competition, gate flags.
A39: § BUILD & SLICE
A40: Custom Scenario | B40: Build your own: override the supplier per cell, recomputes live.
A41: Custom Dashboard | B41: Your build's lenses LIVE — spend, savings, share, transit move too.
A42: Data (pivot me) | B42: Slice it yourself: a flat Excel Table to drop a native PivotTable on.

Sheet Controls
A1: Controls & Assumptions — how this cycle was run
A2: Spring 2026 Tomatoes Cycle
A3: DECISION-SUPPORT — recommends, does not assert
A5: Cycle
A6: Commodity | B6: Field Tomatoes
A7: Cycle code | B7: CYC-20260621-30BC
A8: Horizon (weeks) | B8: 13
A9: Timeframes (seasons) | B9: 1
A10: Rounds run | B10: 2
A11: Scope
A12: DCs | B12: 2
A13: Lots (items) | B13: 2
A14: Suppliers invited | B14: 2
A15: Total projected cases (period) | B15: 20800
A16: Baselines
A17: Incumbent baseline spend (iTrade routing) | B17: 280800
A18: STLY baseline (modeled — iTrade pending) | B18: 292032
A19: Recommended (Scenario B) spend | B19: 218400
A20: Savings vs incumbent (period $) | B20: 62400
A21: Negotiation savings R1→Final (period $) | B21: 0
A22: Engine weights
A23: Price weight | B23: 0.31
A24: Coverage weight | B24: 0.22
A25: Historical weight | B25: 0.18
A26: Z-Risk weight | B26: 0.09
A27: Continuity weight | B27: 0.2
A28: Engine rules
A29: Max suppliers per DC (split cap) | B29: 2
A30: Concentration flag threshold | B30: 0.4
A31: Global premium ceiling | B31: 0.12
A32: Coverage eligibility floor | B32: 0.8
A34: Schema-backed: incumbent baseline, savings, weights, rules, rounds. Modeled (pending real feeds): STLY uplift (iTrade), product type — labelled where shown.

Sheet Award Summary
A1: Award Summary (Sign-off) — Recommended: Scenario B (Risk-adjusted recommendation)
A2: Per DC: incumbent → recommended, savings in $ vs TWO baselines + negotiation capture
A3: DECISION-SUPPORT — recommends, does not assert
A5: DC | B5: Incumbent | C5: Recommended | D5: Cells | E5: Rec spend (period) | F5: Incumbent baseline | G5: Savings vs incumbent $ | H5: Savings vs incumbent % | I5: Savings vs STLY $ | J5: Negotiation R1→Final $
A6: Atlanta DC | B6: Green Valley Farms | C6: Green Valley Farms, Sunbelt Produce | D6: 2 | E6: 109200 | F6: 140400 | G6: 31200 | H6: 0.22222222 | I6: 36816 | J6: 0
A7: Dallas DC | B7: Green Valley Farms | C7: Green Valley Farms, Sunbelt Produce | D7: 2 | E7: 109200 | F7: 140400 | G7: 31200 | H7: 0.22222222 | I7: 36816 | J7: 0
A8: TOTAL | D8: =SUM(D6:D7) | E8: =SUM(E6:E7) | F8: =SUM(F6:F7) | G8: =SUM(G6:G7) | H8: =G8/F8 | I8: =SUM(I6:I7) | J8: =SUM(J6:J7)
A11: By product type (Conventional / Organic)
A12: Product type | B12: Rec spend | C12: Baseline | D12: Savings $ | E12: Savings %
A13: Conventional | B13: 218400 | C13: 280800 | D13: 62400 | E13: 0.22222222

Sheet Scenario Comparison
A1: SCENARIO COMPARISON — lenses side by side + LIVE Custom + drill (which lens?)
A2: Rows A-G = the lenses; the Cust row is LIVE off the Custom Scenario tab (change a pick there and Custom spend / Δ vs A / savings update here). A = benchmark (peach), B = recommendation (blue).
A3: ▶ DRILL: below this table each scenario TOTAL expands (+ in the margin) to per-DC, then to per-supplier — opens collapsed to totals, expand for depth on demand (D27).
A4: *Savings vs STLY uses a MODELED prior-year baseline (no live STLY feed yet: prior-year actual-paid modeled ~4% over this year's incumbent routing). Clearly labelled an estimate.
A5: LIVE CYCLE DATA · baseline $280,800 · STLY* $292,032 · DECISION-SUPPORT — recommends, does not assert
A6: Lens | B6: Scenario (label) | C6: Total Spend | D6: Δ vs A (lowest-cost) | E6: Savings vs Baseline | F6: Savings vs STLY* | G6: # Suppliers | H6: # Cap-Breaches | I6: # Cells
A7: A | B7: Lowest-cost reference | C7: 218400 | D7: 0 | E7: 0.22222222 | F7: 0.25213675 | G7: 2 | H7: 0 | I7: 4
A8: B | B8: Risk-adjusted recommendation | C8: 218400 | D8: 0 | E8: 0.22222222 | F8: 0.25213675 | G8: 2 | H8: 0 | I8: 4
A9: C | B9: Incumbent defense | C9: 218400 | D9: 0 | E9: 0.22222222 | F9: 0.25213675 | G9: 2 | H9: 0 | I9: 4
A10: D | B10: Max-N per DC | C10: 218400 | D10: 0 | E10: 0.22222222 | F10: 0.25213675 | G10: 2 | H10: 0 | I10: 4
A11: E | B11: Exclusion applied | C11: 218400 | D11: 0 | E11: 0.22222222 | F11: 0.25213675 | G11: 2 | H11: 0 | I11: 4
A12: F | B12: Custom override | C12: 218400 | D12: 0 | E12: 0.22222222 | F12: 0.25213675 | G12: 2 | H12: 0 | I12: 4
A13: G | B13: Preferred supplier | C13: 218400 | D13: 0 | E13: 0.22222222 | F13: 0.25213675 | G13: 2 | H13: 0 | I13: 4
A14: Cust | B14: Custom build (LIVE — off Custom Scenario tab) | C14: ='Custom Scenario'!$K$11 | D14: ='Custom Scenario'!$K$11-$C$7 | E14: =IF(280800.000000000=0,0,(280800.000000000-'Custom Scenario'!$K$11)/280800.000000000) | F14: =IF(292032.00=0,0,(292032.00-'Custom Scenario'!$K$11)/292032.00) | G14: =SUMPRODUCT(('Custom Scenario'!$E$7:$E$10<>"")/COUNTIF('Custom Scenario'!$E$7:$E$10,'Custom Scenario'!$E$7:$E$10&"")) | H14: (see Custom tab) | I14: 4
A16: DRILL-DOWN — expand a scenario (+) to per-DC, then to per-supplier (D27)
A17: Scenario / DC / Supplier | B17: Spend | C17: Volume (cases) | D17: Savings vs Baseline ($) | E17: # Suppliers / $/case | F17: Volume share | G17: Premium vs Baseline | H17: Flags
A18: Scenario A — Lowest-cost reference | B18: 218400 | C18: 20800 | D18: 62400 | E18: 2
A19: Atlanta DC | B19: 109200 | C19: 10400 | D19: 31200 | E19: 2
A20: Green Valley Farms | B20: 54600 | C20: 5200 | D20: 15600 | E20: 10.5 | F20: 1 | G20: -0.22222222 | H20: INCUMBENT
A21: Sunbelt Produce | B21: 54600 | C21: 5200 | D21: 15600 | E21: 10.5 | F21: 1 | G21: -0.22222222 | H21: —
A22: Dallas DC | B22: 109200 | C22: 10400 | D22: 31200 | E22: 2
A23: Green Valley Farms | B23: 54600 | C23: 5200 | D23: 15600 | E23: 10.5 | F23: 1 | G23: -0.22222222 | H23: INCUMBENT
A24: Sunbelt Produce | B24: 54600 | C24: 5200 | D24: 15600 | E24: 10.5 | F24: 1 | G24: -0.22222222 | H24: —
A25: Scenario B — Risk-adjusted recommendation | B25: 218400 | C25: 20800 | D25: 62400 | E25: 2
A26: Atlanta DC | B26: 109200 | C26: 10400 | D26: 31200 | E26: 2
A27: Green Valley Farms | B27: 54600 | C27: 5200 | D27: 15600 | E27: 10.5 | F27: 1 | G27: -0.22222222 | H27: INCUMBENT
A28: Sunbelt Produce | B28: 54600 | C28: 5200 | D28: 15600 | E28: 10.5 | F28: 1 | G28: -0.22222222 | H28: —
A29: Dallas DC | B29: 109200 | C29: 10400 | D29: 31200 | E29: 2
A30: Green Valley Farms | B30: 54600 | C30: 5200 | D30: 15600 | E30: 10.5 | F30: 1 | G30: -0.22222222 | H30: INCUMBENT
A31: Sunbelt Produce | B31: 54600 | C31: 5200 | D31: 15600 | E31: 10.5 | F31: 1 | G31: -0.22222222 | H31: —
A32: Scenario C — Incumbent defense | B32: 218400 | C32: 20800 | D32: 62400 | E32: 2
A33: Atlanta DC | B33: 109200 | C33: 10400 | D33: 31200 | E33: 2
A34: Green Valley Farms | B34: 54600 | C34: 5200 | D34: 15600 | E34: 10.5 | F34: 1 | G34: -0.22222222 | H34: INCUMBENT
A35: Sunbelt Produce | B35: 54600 | C35: 5200 | D35: 15600 | E35: 10.5 | F35: 1 | G35: -0.22222222 | H35: —
A36: Dallas DC | B36: 109200 | C36: 10400 | D36: 31200 | E36: 2
A37: Green Valley Farms | B37: 54600 | C37: 5200 | D37: 15600 | E37: 10.5 | F37: 1 | G37: -0.22222222 | H37: INCUMBENT
A38: Sunbelt Produce | B38: 54600 | C38: 5200 | D38: 15600 | E38: 10.5 | F38: 1 | G38: -0.22222222 | H38: —
A39: Scenario D — Max-N per DC | B39: 218400 | C39: 20800 | D39: 62400 | E39: 2
A40: Atlanta DC | B40: 109200 | C40: 10400 | D40: 31200 | E40: 2
A41: Green Valley Farms | B41: 54600 | C41: 5200 | D41: 15600 | E41: 10.5 | F41: 1 | G41: -0.22222222 | H41: INCUMBENT
...

Sheet Lowest-Cost Check
A1: LOWEST-COST CHECK — is the recommendation the cheapest? if not, why?
A2: Per cell: the Scenario B pick vs the market-low bid. Premium = the risk-adjusted cost traded for coverage/continuity. A = the lowest-cost benchmark.
A3: LIVE CYCLE DATA · DECISION-SUPPORT — recommends, does not assert
A6: DC | B6: Lot | C6: Item | D6: Timeframe | E6: Recommended | F6: Rec $/case | G6: Market-low $/case | H6: Premium vs Low | I6: Is Lowest? | J6: Why not lowest
A7: Atlanta DC | B7: Lot 1 - Grape | C7: Premium Grape Tomato 10oz | D7: Spring 2026 | E7: Green Valley Farms | F7: 10.5 | G7: 10.5 | H7: 0 | I7: Yes | J7: Recommended pick IS the market-low bid (the floor).
A8: Atlanta DC | B8: Lot 2 - Roma | C8: Roma Tomato Bulk 25lb | D8: Spring 2026 | E8: Sunbelt Produce | F8: 10.5 | G8: 10.5 | H8: 0 | I8: Yes | J8: Recommended pick IS the market-low bid (the floor).
A9: Dallas DC | B9: Lot 1 - Grape | C9: Premium Grape Tomato 10oz | D9: Spring 2026 | E9: Green Valley Farms | F9: 10.5 | G9: 10.5 | H9: 0 | I9: Yes | J9: Recommended pick IS the market-low bid (the floor).
A10: Dallas DC | B10: Lot 2 - Roma | C10: Roma Tomato Bulk 25lb | D10: Spring 2026 | E10: Sunbelt Produce | F10: 10.5 | G10: 10.5 | H10: 0 | I10: Yes | J10: Recommended pick IS the market-low bid (the floor).

Sheet Supplier Comparison
A1: SUPPLIER COMPARISON — every supplier per cell, side by side (the FOB comparison)
A2: Each row = one DC × lot × item × TF cell. Left block = each supplier's all-in $/case (blank = no bid). GREEN = lowest (best) price per row. Recommended pick = bold blue; incumbent = amber.
A3: Right block = cost impact vs baseline % per supplier (the premium each carries). Min $/case, Recommended supplier + RecScore in the middle.
A4: LIVE CYCLE DATA · 2 suppliers · DECISION-SUPPORT — recommends, does not assert
A7: DC | B7: Lot | C7: Item | D7: Timeframe | E7: Demand (cases) | F7: Baseline $/case | G7: Incumbent | H7: Incumbent $/case | I7: Green Valley Farms | J7: Sunbelt Produce | K7: Min $/case | L7: Recommended | M7: RecScore | N7: Green Valley Farms (impact) | O7: Sunbelt Produce (impact)
A8: Atlanta DC | B8: Lot 1 - Grape | C8: Premium Grape Tomato 10oz | D8: Spring 2026 | E8: 5200 | F8: 13.5 | G8: Green Valley Farms | H8: 10.5 | I8: 10.5 | J8: 11.8 | K8: 10.5 | L8: Green Valley Farms | M8: 98.9 | N8: -0.22222222 | O8: -0.12592593
A9: Atlanta DC | B9: Lot 2 - Roma | C9: Roma Tomato Bulk 25lb | D9: Spring 2026 | E9: 5200 | F9: 13.5 | G9: Green Valley Farms | H9: 11.8 | I9: 11.8 | J9: 10.5 | K9: 10.5 | L9: Sunbelt Produce | M9: 78.9 | N9: -0.12592593 | O9: -0.22222222
A10: Dallas DC | B10: Lot 1 - Grape | C10: Premium Grape Tomato 10oz | D10: Spring 2026 | E10: 5200 | F10: 13.5 | G10: Green Valley Farms | H10: 10.5 | I10: 10.5 | J10: 11.8 | K10: 10.5 | L10: Green Valley Farms | M10: 98.9 | N10: -0.22222222 | O10: -0.12592593
A11: Dallas DC | B11: Lot 2 - Roma | C11: Roma Tomato Bulk 25lb | D11: Spring 2026 | E11: 5200 | F11: 13.5 | G11: Green Valley Farms | H11: 11.8 | I11: 11.8 | J11: 10.5 | K11: 10.5 | L11: Sunbelt Produce | M11: 78.9 | N11: -0.12592593 | O11: -0.22222222
A12: TOTAL | E12: =SUM(E8:E11)

Sheet Landed & Hidden Costs
A1: Landed & Hidden Costs — farm-gate + freight = landed, plus transit/freshness
A2: Cheapest LANDED bid per (lot, DC) green · freight = Delivery + VegCool · transit > 4d = freshness watch (hidden cost)
A3: DECISION-SUPPORT — recommends, does not assert
A5: Lot | B5: DC | C5: Region | D5: Supplier | E5: FOB $/case | F5: + Delivery | G5: + VegCool | H5: = All-In $/case | I5: Freight % of All-In | J5: Transit (days) | K5: Freshness
A6: Lot 1 - Grape | B6: Atlanta DC | C6: East | D6: Green Valley Farms | E6: 9.5 | F6: 0 | G6: 0 | H6: 10.5 | I6: 0 | J6: — | K6: —
A7: Lot 1 - Grape | B7: Atlanta DC | C7: East | D7: Sunbelt Produce | E7: 10.8 | F7: 0 | G7: 0 | H7: 11.8 | I7: 0 | J7: — | K7: —
A8: Lot 1 - Grape | B8: Dallas DC | C8: South | D8: Green Valley Farms | E8: 9.5 | F8: 0 | G8: 0 | H8: 10.5 | I8: 0 | J8: — | K8: —
A9: Lot 1 - Grape | B9: Dallas DC | C9: South | D9: Sunbelt Produce | E9: 10.8 | F9: 0 | G9: 0 | H9: 11.8 | I9: 0 | J9: — | K9: —
A10: Lot 2 - Roma | B10: Atlanta DC | C10: East | D10: Sunbelt Produce | E10: 9.5 | F10: 0 | G10: 0 | H10: 10.5 | I10: 0 | J10: — | K10: —
A11: Lot 2 - Roma | B11: Atlanta DC | C11: East | D11: Green Valley Farms | E11: 10.8 | F11: 0 | G11: 0 | H11: 11.8 | I11: 0 | J11: — | K11: —
A12: Lot 2 - Roma | B12: Dallas DC | C12: South | D12: Sunbelt Produce | E12: 9.5 | F12: 0 | G12: 0 | H12: 10.5 | I12: 0 | J12: — | K12: —
A13: Lot 2 - Roma | B13: Dallas DC | C13: South | D13: Green Valley Farms | E13: 10.8 | F13: 0 | G13: 0 | H13: 11.8 | I13: 0 | J13: — | K13: —
A16: Regional freight (avg Delivery $/case by lane)
A17: Region | B17: Avg Delivery $/case | C17: Lanes
A18: East | B18: 0 | C18: 4
A19: South | B19: 0 | C19: 4

Sheet Share & Relationships
A1: Share & Relationships — who carries the business, and the relationship behind it
A2: Preserve = incumbent kept · Create = new supplier earned in · Dependency = share ≥ 40% (concentration risk)
A3: DECISION-SUPPORT — recommends, does not assert
A6: Supplier | B6: Relationship | C6: A share | D6: B share | E6: C share | F6: D share | G6: E share | H6: F share | I6: G share | J6: Max share | K6: Dependency?
A7: Green Valley Farms | B7: Preserve | C7: 0.5 | D7: 0.5 | E7: 0.5 | F7: 0.5 | G7: 0.5 | H7: 0.5 | I7: 0.5 | J7: 0.5 | K7: DEPENDENCY
A8: Sunbelt Produce | B8: Create | C8: 0.5 | D8: 0.5 | E8: 0.5 | F8: 0.5 | G8: 0.5 | H8: 0.5 | I8: 0.5 | J8: 0.5 | K8: DEPENDENCY
A11: Relationship ledger — Scenario B (recommended)
A12: Relationships PRESERVED (incumbent retained) | B12: Green Valley Farms
A13: Relationships CREATED (new supplier earned in) | B13: Sunbelt Produce
A14: Incumbents NOT awarded (relationship at risk) | B14: —

Sheet Incumbent Retention
A1: Incumbent Retention — what keeping each incumbent costs vs. the recommendation
A2: The engine recommends on economics and already keeps a price-eligible incumbent on a near-tie. 'Gated by premium' = the incumbent's bid is over the eligibility ceiling, so the engine excludes it — retaining is a recorded override, never silently paid.
A3: Δ to retain = incumbent − recommendation; Premium to retain $ = Δ × period cases. Sort/keep what the relationship is worth. DECISION-SUPPORT — recommends, does not assert
A5: DC | B5: Lot | C5: TF | D5: Incumbent | E5: Incumbent $/case | F5: Status | G5: Recommended | H5: Rec $/case | I5: Δ to retain $/case | J5: Period cases | K5: Premium to retain $ | L5: Retain? (your call)
A6: Atlanta DC | B6: Lot 2 - Roma | C6: Spring 2026 | D6: Green Valley Farms | E6: 11.8 | F6: Gated by premium | G6: Sunbelt Produce | H6: 10.5 | I6: 1.3 | J6: 5200 | K6: 6760
A7: Dallas DC | B7: Lot 2 - Roma | C7: Spring 2026 | D7: Green Valley Farms | E7: 11.8 | F7: Gated by premium | G7: Sunbelt Produce | H7: 10.5 | I7: 1.3 | J7: 5200 | K7: 6760
A8: Atlanta DC | B8: Lot 1 - Grape | C8: Spring 2026 | D8: Green Valley Farms | E8: 10.5 | F8: Retained — recommended | G8: Green Valley Farms | H8: 10.5 | I8: 0 | J8: 5200 | K8: 0
A9: Dallas DC | B9: Lot 1 - Grape | C9: Spring 2026 | D9: Green Valley Farms | E9: 10.5 | F9: Retained — recommended | G9: Green Valley Farms | H9: 10.5 | I9: 0 | J9: 5200 | K9: 0
A10: RELATIONSHIP BUDGET — premium to retain every non-recommended incumbent | K10: =SUM(K6:K9)
A13: Incumbent picture — counts by status + the relationship budget at stake
A14: Retained — recommended (engine kept the incumbent) | D14: 2
A15: Eligible — not the pick (in range, lost on score) | D15: 0
A16: Gated by premium (over the ceiling — override to keep) | D16: 2
A17: No bid (incumbent did not bid) | D17: 0
A18: Relationship budget — premium to retain every non-recommended incumbent that bid | D18: 13520

Sheet Negotiation Dynamics
A1: Negotiation Dynamics — are you being treated fairly? (repeated game, asym. info)
A2: Concession = R1→Final move (more negative = conceded more) · predictable in process, flexible only where economics justify
A3: DECISION-SUPPORT — recommends, does not assert
A6: Supplier | B6: Role | C6: Cells moved | D6: Avg move R1→Final | E6: Avg premium vs low | F6: Sustainability flags | G6: Negotiation read
A7: Green Valley Farms | B7: Incumbent | C7: 0 | D7: 0 | E7: 0.061904762 | F7: 0 | G7: Holding the installed base — test the leverage
A8: Sunbelt Produce | B8: Challenger | C8: 0 | D8: 0 | E8: 0.061904762 | F8: 0 | G8: Competing in line with the field
A11: Fairness read — incumbent concession vs the field
A12: The incumbent (0.0%) moved in line with the field (0.0%) — competitive, no obvious leverage play.

Sheet Coverage
A1: COVERAGE — offered vs required volume (capacity reality next to price)
A2: Offered vs required cases → cover ratio + band. The 80% floor is the eligibility gate; Short/Critical bands flag capacity risk (advisory).
A3: LIVE CYCLE DATA · DECISION-SUPPORT — recommends, does not assert
A6: DC | B6: Lot | C6: Timeframe | D6: Supplier | E6: $/case | F6: Req (cases) | G6: Offered (cases) | H6: Cover Ratio | I6: Band | J6: Eligible? | K6: Rec?
A7: Atlanta DC | B7: Lot 1 - Grape | C7: Spring 2026 | D7: Green Valley Farms | E7: 10.5 | F7: 5200 | G7: 7800 | H7: 1.5 | I7: Surplus (>120%) | J7: Yes | K7: Yes
A8: Atlanta DC | B8: Lot 1 - Grape | C8: Spring 2026 | D8: Sunbelt Produce | E8: 11.8 | F8: 5200 | G8: 7800 | H8: 1.5 | I8: Surplus (>120%) | J8: No | K8: —
A9: Atlanta DC | B9: Lot 2 - Roma | C9: Spring 2026 | D9: Green Valley Farms | E9: 11.8 | F9: 5200 | G9: 7800 | H9: 1.5 | I9: Surplus (>120%) | J9: No | K9: —
A10: Atlanta DC | B10: Lot 2 - Roma | C10: Spring 2026 | D10: Sunbelt Produce | E10: 10.5 | F10: 5200 | G10: 7800 | H10: 1.5 | I10: Surplus (>120%) | J10: Yes | K10: Yes
A11: Dallas DC | B11: Lot 1 - Grape | C11: Spring 2026 | D11: Green Valley Farms | E11: 10.5 | F11: 5200 | G11: 7800 | H11: 1.5 | I11: Surplus (>120%) | J11: Yes | K11: Yes
A12: Dallas DC | B12: Lot 1 - Grape | C12: Spring 2026 | D12: Sunbelt Produce | E12: 11.8 | F12: 5200 | G12: 7800 | H12: 1.5 | I12: Surplus (>120%) | J12: No | K12: —
A13: Dallas DC | B13: Lot 2 - Roma | C13: Spring 2026 | D13: Green Valley Farms | E13: 11.8 | F13: 5200 | G13: 7800 | H13: 1.5 | I13: Surplus (>120%) | J13: No | K13: —
A14: Dallas DC | B14: Lot 2 - Roma | C14: Spring 2026 | D14: Sunbelt Produce | E14: 10.5 | F14: 5200 | G14: 7800 | H14: 1.5 | I14: Surplus (>120%) | J14: Yes | K14: Yes

Sheet Detailed Scoring
A1: DETAILED SCORING — the five factors + the market stats that explain them
A2: Per scored bid (final round). Market stats (Mkt Min/Avg, Prem vs Low, Z-Score, # bidders) explain the factor scores → RecScore. Eligible? = passed the gates. REC = Scenario B pick; INC = incumbent.
A3: LIVE CYCLE DATA · DECISION-SUPPORT — recommends, does not assert
A5: DC | B5: Lot | C5: Timeframe | D5: Supplier | E5: $/case | F5: Mkt Min | G5: Mkt Avg | H5: Prem vs Low | I5: Z-Score | J5: # Bidders | K5: Price | L5: Cov | M5: Hist | N5: Z-Risk | O5: Cont | P5: RecScore | Q5: Eligible? | R5: Rec/Inc | S5: Gate flags
A6: Atlanta DC | B6: Lot 1 - Grape | C6: Spring 2026 | D6: Green Valley Farms | E6: 10.5 | F6: 10.5 | G6: 11.15 | H6: 0 | I6: -1 | J6: 2 | K6: 100 | L6: 95 | M6: 100 | N6: 100 | O6: 100 | P6: 98.9 | Q6: Yes | R6: REC·INC | S6: Low bidder count (<3): Z-score less reliable
A7: Atlanta DC | B7: Lot 1 - Grape | C7: Spring 2026 | D7: Sunbelt Produce | E7: 11.8 | F7: 10.5 | G7: 11.15 | H7: 0.12380952 | I7: 1 | J7: 2 | K7: 20 | L7: 95 | M7: 100 | N7: 100 | O7: 0 | P7: 54.1 | Q7: No | R7: — | S7: Price premium exceeds threshold; Low bidder count (<3): Z-score less reliable
A8: Atlanta DC | B8: Lot 2 - Roma | C8: Spring 2026 | D8: Sunbelt Produce | E8: 10.5 | F8: 10.5 | G8: 11.15 | H8: 0 | I8: -1 | J8: 2 | K8: 100 | L8: 95 | M8: 100 | N8: 100 | O8: 0 | P8: 78.9 | Q8: Yes | R8: REC | S8: Low bidder count (<3): Z-score less reliable
A9: Atlanta DC | B9: Lot 2 - Roma | C9: Spring 2026 | D9: Green Valley Farms | E9: 11.8 | F9: 10.5 | G9: 11.15 | H9: 0.12380952 | I9: 1 | J9: 2 | K9: 20 | L9: 95 | M9: 100 | N9: 100 | O9: 100 | P9: 74.1 | Q9: No | R9: INC | S9: Price premium exceeds threshold; Low bidder count (<3): Z-score less reliable
A10: Dallas DC | B10: Lot 1 - Grape | C10: Spring 2026 | D10: Green Valley Farms | E10: 10.5 | F10: 10.5 | G10: 11.15 | H10: 0 | I10: -1 | J10: 2 | K10: 100 | L10: 95 | M10: 100 | N10: 100 | O10: 100 | P10: 98.9 | Q10: Yes | R10: REC·INC | S10: Low bidder count (<3): Z-score less reliable
A11: Dallas DC | B11: Lot 1 - Grape | C11: Spring 2026 | D11: Sunbelt Produce | E11: 11.8 | F11: 10.5 | G11: 11.15 | H11: 0.12380952 | I11: 1 | J11: 2 | K11: 20 | L11: 95 | M11: 100 | N11: 100 | O11: 0 | P11: 54.1 | Q11: No | R11: — | S11: Price premium exceeds threshold; Low bidder count (<3): Z-score less reliable
A12: Dallas DC | B12: Lot 2 - Roma | C12: Spring 2026 | D12: Sunbelt Produce | E12: 10.5 | F12: 10.5 | G12: 11.15 | H12: 0 | I12: -1 | J12: 2 | K12: 100 | L12: 95 | M12: 100 | N12: 100 | O12: 0 | P12: 78.9 | Q12: Yes | R12: REC | S12: Low bidder count (<3): Z-score less reliable
A13: Dallas DC | B13: Lot 2 - Roma | C13: Spring 2026 | D13: Green Valley Farms | E13: 11.8 | F13: 10.5 | G13: 11.15 | H13: 0.12380952 | I13: 1 | J13: 2 | K13: 20 | L13: 95 | M13: 100 | N13: 100 | O13: 100 | P13: 74.1 | Q13: No | R13: INC | S13: Price premium exceeds threshold; Low bidder count (<3): Z-score less reliable

Sheet Data Quality
A1: DATA QUALITY — surfaced, never hidden, never fatal
A2: The data-quality conditions the team should see before aligning. All non-blocking (decision-support) — the run completes and recommends; the human reviews these.
A3: LIVE CYCLE DATA · DECISION-SUPPORT — recommends, does not assert
A6: Flag | B6: Count | C6: Detail / Action
A7: No-bid cells (supplier × cell with no priced bid) | B7: 0 | C7: Suppliers that did not price a cell. Expected (suppliers decline cells); the cell is still scored from those who bid. Non-blocking.
A8: Thin-competition cells (<3 bidders) | B8: 4 | C8: Cells with fewer than 3 priced bids — the Z-score is less reliable; advisory flag, the bid stays eligible.
A9: Bids carrying an advisory gate flag | B9: 8 | C9: Outlier / low-bidder-count notes accumulated in gate_flags. Advisory — does not by itself make a bid ineligible.
A10: Bids gated ineligible | B10: 4 | C10: Failed a hard gate (no valid price / premium over ceiling / coverage < floor). Scored but not awardable. Recommends-not-asserts: surfaced for review.

Sheet _Prices
A1: Match Key | B1: Cell Key | C1: Supplier | D1: $/case | E1: Transit (days) | F1: Cell Key | G1: Min $/case | H1: Incumbent $/case | I1: Baseline $/case
A2: DC01|LOT-01|TF01@Green Valley Farms | B2: DC01|LOT-01|TF01 | C2: Green Valley Farms | D2: 10.5 | F2: DC01|LOT-01|TF01 | G2: 10.5 | H2: 10.5 | I2: 13.5
A3: DC01|LOT-01|TF01@Sunbelt Produce | B3: DC01|LOT-01|TF01 | C3: Sunbelt Produce | D3: 11.8 | F3: DC01|LOT-02|TF01 | G3: 10.5 | H3: 11.8 | I3: 13.5
A4: DC01|LOT-02|TF01@Green Valley Farms | B4: DC01|LOT-02|TF01 | C4: Green Valley Farms | D4: 11.8 | F4: DC02|LOT-01|TF01 | G4: 10.5 | H4: 10.5 | I4: 13.5
A5: DC01|LOT-02|TF01@Sunbelt Produce | B5: DC01|LOT-02|TF01 | C5: Sunbelt Produce | D5: 10.5 | F5: DC02|LOT-02|TF01 | G5: 10.5 | H5: 11.8 | I5: 13.5
A6: DC02|LOT-01|TF01@Green Valley Farms | B6: DC02|LOT-01|TF01 | C6: Green Valley Farms | D6: 10.5
A7: DC02|LOT-01|TF01@Sunbelt Produce | B7: DC02|LOT-01|TF01 | C7: Sunbelt Produce | D7: 11.8
A8: DC02|LOT-02|TF01@Green Valley Farms | B8: DC02|LOT-02|TF01 | C8: Green Valley Farms | D8: 11.8
A9: DC02|LOT-02|TF01@Sunbelt Produce | B9: DC02|LOT-02|TF01 | C9: Sunbelt Produce | D9: 10.5

Sheet Custom Scenario
A1: CUSTOM SCENARIO — override the supplier per cell, watch it recompute LIVE
A2: ▶ Change the Supplier dropdown on any row — $/case, vs Min/Incumbent/Baseline, Total Spend, Savings + Cap-Breach all update live.
A3: Opens on Scenario B's recommendation. Dropdown lists only the eligible suppliers for that cell (by name). Grounded in the Supplier Comparison.
A4: LIVE CYCLE DATA · max 2 suppliers/DC · DECISION-SUPPORT — recommends, does not assert
A6: DC | B6: Lot | C6: Item | D6: Timeframe | E6: Supplier (change me ▼) | F6: $/case (live) | G6: vs Min (live) | H6: vs Incumbent (live) | I6: vs Baseline (live) | J6: Volume (cases) | K6: Line Spend (live) | L6: Baseline $/case | M6: Cell Key | N6: Transit days (live)
A7: Atlanta DC | B7: Lot 1 - Grape | C7: Premium Grape Tomato 10oz | D7: Spring 2026 | E7: Green Valley Farms | F7: =SUMIFS('_Prices'!$D:$D,'_Prices'!$A:$A,M7&"@"&E7) | G7: =IF(SUMIFS('_Prices'!$G:$G,'_Prices'!$F:$F,M7)=0,0,(F7-SUMIFS('_Prices'!$G:$G,'_Prices'!$F:$F,M7))/SUMIFS('_Prices'!$G:$G,'_Prices'!$F:$F,M7)) | H7: =IF(SUMIFS('_Prices'!$H:$H,'_Prices'!$F:$F,M7)=0,0,(F7-SUMIFS('_Prices'!$H:$H,'_Prices'!$F:$F,M7))/SUMIFS('_Prices'!$H:$H,'_Prices'!$F:$F,M7)) | I7: =IF(L7=0,0,(F7-L7)/L7) | J7: 5200 | K7: =F7*J7 | L7: 13.5 | M7: DC01|LOT-01|TF01 | N7: =SUMIFS('_Prices'!$E:$E,'_Prices'!$A:$A,M7&"@"&E7)
A8: Atlanta DC | B8: Lot 2 - Roma | C8: Roma Tomato Bulk 25lb | D8: Spring 2026 | E8: Sunbelt Produce | F8: =SUMIFS('_Prices'!$D:$D,'_Prices'!$A:$A,M8&"@"&E8) | G8: =IF(SUMIFS('_Prices'!$G:$G,'_Prices'!$F:$F,M8)=0,0,(F8-SUMIFS('_Prices'!$G:$G,'_Prices'!$F:$F,M8))/SUMIFS('_Prices'!$G:$G,'_Prices'!$F:$F,M8)) | H8: =IF(SUMIFS('_Prices'!$H:$H,'_Prices'!$F:$F,M8)=0,0,(F8-SUMIFS('_Prices'!$H:$H,'_Prices'!$F:$F,M8))/SUMIFS('_Prices'!$H:$H,'_Prices'!$F:$F,M8)) | I8: =IF(L8=0,0,(F8-L8)/L8) | J8: 5200 | K8: =F8*J8 | L8: 13.5 | M8: DC01|LOT-02|TF01 | N8: =SUMIFS('_Prices'!$E:$E,'_Prices'!$A:$A,M8&"@"&E8)
A9: Dallas DC | B9: Lot 1 - Grape | C9: Premium Grape Tomato 10oz | D9: Spring 2026 | E9: Green Valley Farms | F9: =SUMIFS('_Prices'!$D:$D,'_Prices'!$A:$A,M9&"@"&E9) | G9: =IF(SUMIFS('_Prices'!$G:$G,'_Prices'!$F:$F,M9)=0,0,(F9-SUMIFS('_Prices'!$G:$G,'_Prices'!$F:$F,M9))/SUMIFS('_Prices'!$G:$G,'_Prices'!$F:$F,M9)) | H9: =IF(SUMIFS('_Prices'!$H:$H,'_Prices'!$F:$F,M9)=0,0,(F9-SUMIFS('_Prices'!$H:$H,'_Prices'!$F:$F,M9))/SUMIFS('_Prices'!$H:$H,'_Prices'!$F:$F,M9)) | I9: =IF(L9=0,0,(F9-L9)/L9) | J9: 5200 | K9: =F9*J9 | L9: 13.5 | M9: DC02|LOT-01|TF01 | N9: =SUMIFS('_Prices'!$E:$E,'_Prices'!$A:$A,M9&"@"&E9)
A10: Dallas DC | B10: Lot 2 - Roma | C10: Roma Tomato Bulk 25lb | D10: Spring 2026 | E10: Sunbelt Produce | F10: =SUMIFS('_Prices'!$D:$D,'_Prices'!$A:$A,M10&"@"&E10) | G10: =IF(SUMIFS('_Prices'!$G:$G,'_Prices'!$F:$F,M10)=0,0,(F10-SUMIFS('_Prices'!$G:$G,'_Prices'!$F:$F,M10))/SUMIFS('_Prices'!$G:$G,'_Prices'!$F:$F,M10)) | H10: =IF(SUMIFS('_Prices'!$H:$H,'_Prices'!$F:$F,M10)=0,0,(F10-SUMIFS('_Prices'!$H:$H,'_Prices'!$F:$F,M10))/SUMIFS('_Prices'!$H:$H,'_Prices'!$F:$F,M10)) | I10: =IF(L10=0,0,(F10-L10)/L10) | J10: 5200 | K10: =F10*J10 | L10: 13.5 | M10: DC02|LOT-02|TF01 | N10: =SUMIFS('_Prices'!$E:$E,'_Prices'!$A:$A,M10&"@"&E10)
A11: TOTAL (live) | J11: =SUM(J7:J10) | K11: =SUM(K7:K10)
D13: Total Custom Spend (live): | E13: =K11
D14: Baseline Spend (incumbent routing): | E14: 280800
D15: Savings vs Baseline ($, live): | E15: =E14-E13
D16: Savings vs Baseline (%, live): | E16: =IF(E14=0,0,(E14-E13)/E14)
D18: Cap-breach check — distinct suppliers per DC (cap = 2): | E18: # suppliers
D19: Atlanta DC | E19: =SUMPRODUCT(($A$7:$A$10="Atlanta DC")/COUNTIFS($A$7:$A$10,$A$7:$A$10,$E$7:$E$10,$E$7:$E$10)) | F19: =IF(E19>2,"⚠ CAP BREACH","OK")
D20: Dallas DC | E20: =SUMPRODUCT(($A$7:$A$10="Dallas DC")/COUNTIFS($A$7:$A$10,$A$7:$A$10,$E$7:$E$10,$E$7:$E$10)) | F20: =IF(E20>2,"⚠ CAP BREACH","OK")

Sheet Custom Dashboard
A1: Custom Dashboard — LIVE off your Custom Scenario build
A2: Change a supplier on the Custom Scenario tab and every number here recomputes.
A3: DECISION-SUPPORT — recommends, does not assert
A5: Your build vs the recommendation
A6: Metric | B6: Custom (LIVE) | C6: Recommended (B) | D6: Δ vs rec
A7: Total spend | B7: =SUM('Custom Scenario'!$K$7:$K$10) | C7: 218400 | D7: =B7-C7
A8: Savings vs incumbent $ | B8: =SUMPRODUCT('Custom Scenario'!$J$7:$J$10,'Custom Scenario'!$L$7:$L$10)-SUM('Custom Scenario'!$K$7:$K$10) | C8: 62400 | D8: =B8-C8
A9: Savings vs incumbent % | B9: =IFERROR((SUMPRODUCT('Custom Scenario'!$J$7:$J$10,'Custom Scenario'!$L$7:$L$10)-SUM('Custom Scenario'!$K$7:$K$10))/SUMPRODUCT('Custom Scenario'!$J$7:$J$10,'Custom Scenario'!$L$7:$L$10),0) | C9: 0.22222222 | D9: =B9-C9
A10: Avg transit (days, vol-wtd) | B10: =IFERROR(SUMPRODUCT('Custom Scenario'!$J$7:$J$10,'Custom Scenario'!$N$7:$N$10)/SUM('Custom Scenario'!$J$7:$J$10),0) | C10: 0 | D10: =B10-C10
A11: Freshness watches (cells) | B11: =COUNTIF('Custom Scenario'!$N$7:$N$10,">4") | C11: 0 | D11: =B11-C11
A12: Suppliers used | B12: =SUMPRODUCT(1/COUNTIF('Custom Scenario'!$E$7:$E$10,'Custom Scenario'!$E$7:$E$10)) | C12: 2 | D12: =B12-C12
A14: Supplier share — LIVE (relationships & dependency)
A15: Supplier | B15: Role | C15: Custom share | D15: Dependency
A16: Green Valley Farms | B16: Preserve | C16: =IFERROR(SUMIF('Custom Scenario'!$E$7:$E$10,"Green Valley Farms",'Custom Scenario'!$K$7:$K$10)/SUM('Custom Scenario'!$K$7:$K$10),0) | D16: =IF(C16>=0.4,"DEPENDENCY","")
A17: Sunbelt Produce | B17: Create | C17: =IFERROR(SUMIF('Custom Scenario'!$E$7:$E$10,"Sunbelt Produce",'Custom Scenario'!$K$7:$K$10)/SUM('Custom Scenario'!$K$7:$K$10),0) | D17: =IF(C17>=0.4,"DEPENDENCY","")
A19: Spend by DC — LIVE
A20: DC | B20: Custom spend | C20: Savings vs incumbent
A21: Atlanta DC | B21: =SUMIF('Custom Scenario'!$A$7:$A$10,"Atlanta DC",'Custom Scenario'!$K$7:$K$10) | C21: =SUMPRODUCT(('Custom Scenario'!$A$7:$A$10="Atlanta DC")*'Custom Scenario'!$J$7:$J$10*'Custom Scenario'!$L$7:$L$10)-SUMIF('Custom Scenario'!$A$7:$A$10,"Atlanta DC",'Custom Scenario'!$K$7:$K$10)
A22: Dallas DC | B22: =SUMIF('Custom Scenario'!$A$7:$A$10,"Dallas DC",'Custom Scenario'!$K$7:$K$10) | C22: =SUMPRODUCT(('Custom Scenario'!$A$7:$A$10="Dallas DC")*'Custom Scenario'!$J$7:$J$10*'Custom Scenario'!$L$7:$L$10)-SUMIF('Custom Scenario'!$A$7:$A$10,"Dallas DC",'Custom Scenario'!$K$7:$K$10)

Sheet Data (pivot me)
A1: Insert > PivotTable on this table to slice any way you like (by scenario, DC, supplier, lot…). LIVE CYCLE DATA — real names & prices.
A2: Scenario | B2: Scenario Label | C2: DC | D2: Lot | E2: Item | F2: Timeframe | G2: Awarded Supplier | H2: Incumbent | I2: Is Incumbent | J2: Volume (cases) | K2: Volume Share | L2: $/case | M2: Spend | N2: Baseline $/case | O2: Baseline Spend | P2: Savings vs Baseline ($) | Q2: Premium vs Baseline | R2: Price Score | S2: Coverage Score | T2: Historical Score | U2: Z-Risk Score | V2: Continuity Score | W2: RecScore | X2: Cap-Breach | Y2: Fallback | Z2: Transit (days) | AA2: Relationship
A3: A | B3: Lowest-cost reference | C3: Atlanta DC | D3: Lot 1 - Grape | E3: Premium Grape Tomato 10oz | F3: Spring 2026 | G3: Green Valley Farms | H3: Green Valley Farms | I3: Yes | J3: 5200 | K3: 1 | L3: 10.5 | M3: 54600 | N3: 13.5 | O3: 70200 | P3: 15600 | Q3: -0.22222222 | R3: 100 | S3: 95 | T3: 100 | U3: 100 | V3: 100 | W3: 98.9 | X3: No | Y3: No | AA3: Preserve
A4: A | B4: Lowest-cost reference | C4: Atlanta DC | D4: Lot 2 - Roma | E4: Roma Tomato Bulk 25lb | F4: Spring 2026 | G4: Sunbelt Produce | H4: Green Valley Farms | I4: No | J4: 5200 | K4: 1 | L4: 10.5 | M4: 54600 | N4: 13.5 | O4: 70200 | P4: 15600 | Q4: -0.22222222 | R4: 100 | S4: 95 | T4: 100 | U4: 100 | V4: 0 | W4: 78.9 | X4: No | Y4: No | AA4: Create
A5: A | B5: Lowest-cost reference | C5: Dallas DC | D5: Lot 1 - Grape | E5: Premium Grape Tomato 10oz | F5: Spring 2026 | G5: Green Valley Farms | H5: Green Valley Farms | I5: Yes | J5: 5200 | K5: 1 | L5: 10.5 | M5: 54600 | N5: 13.5 | O5: 70200 | P5: 15600 | Q5: -0.22222222 | R5: 100 | S5: 95 | T5: 100 | U5: 100 | V5: 100 | W5: 98.9 | X5: No | Y5: No | AA5: Preserve
A6: A | B6: Lowest-cost reference | C6: Dallas DC | D6: Lot 2 - Roma | E6: Roma Tomato Bulk 25lb | F6: Spring 2026 | G6: Sunbelt Produce | H6: Green Valley Farms | I6: No | J6: 5200 | K6: 1 | L6: 10.5 | M6: 54600 | N6: 13.5 | O6: 70200 | P6: 15600 | Q6: -0.22222222 | R6: 100 | S6: 95 | T6: 100 | U6: 100 | V6: 0 | W6: 78.9 | X6: No | Y6: No | AA6: Create
A7: B | B7: Risk-adjusted recommendation | C7: Atlanta DC | D7: Lot 1 - Grape | E7: Premium Grape Tomato 10oz | F7: Spring 2026 | G7: Green Valley Farms | H7: Green Valley Farms | I7: Yes | J7: 5200 | K7: 1 | L7: 10.5 | M7: 54600 | N7: 13.5 | O7: 70200 | P7: 15600 | Q7: -0.22222222 | R7: 100 | S7: 95 | T7: 100 | U7: 100 | V7: 100 | W7: 98.9 | X7: No | Y7: No | AA7: Preserve
A8: B | B8: Risk-adjusted recommendation | C8: Atlanta DC | D8: Lot 2 - Roma | E8: Roma Tomato Bulk 25lb | F8: Spring 2026 | G8: Sunbelt Produce | H8: Green Valley Farms | I8: No | J8: 5200 | K8: 1 | L8: 10.5 | M8: 54600 | N8: 13.5 | O8: 70200 | P8: 15600 | Q8: -0.22222222 | R8: 100 | S8: 95 | T8: 100 | U8: 100 | V8: 0 | W8: 78.9 | X8: No | Y8: No | AA8: Create
A9: B | B9: Risk-adjusted recommendation | C9: Dallas DC | D9: Lot 1 - Grape | E9: Premium Grape Tomato 10oz | F9: Spring 2026 | G9: Green Valley Farms | H9: Green Valley Farms | I9: Yes | J9: 5200 | K9: 1 | L9: 10.5 | M9: 54600 | N9: 13.5 | O9: 70200 | P9: 15600 | Q9: -0.22222222 | R9: 100 | S9: 95 | T9: 100 | U9: 100 | V9: 100 | W9: 98.9 | X9: No | Y9: No | AA9: Preserve
A10: B | B10: Risk-adjusted recommendation | C10: Dallas DC | D10: Lot 2 - Roma | E10: Roma Tomato Bulk 25lb | F10: Spring 2026 | G10: Sunbelt Produce | H10: Green Valley Farms | I10: No | J10: 5200 | K10: 1 | L10: 10.5 | M10: 54600 | N10: 13.5 | O10: 70200 | P10: 15600 | Q10: -0.22222222 | R10: 100 | S10: 95 | T10: 100 | U10: 100 | V10: 0 | W10: 78.9 | X10: No | Y10: No | AA10: Create
A11: C | B11: Incumbent defense | C11: Atlanta DC | D11: Lot 1 - Grape | E11: Premium Grape Tomato 10oz | F11: Spring 2026 | G11: Green Valley Farms | H11: Green Valley Farms | I11: Yes | J11: 5200 | K11: 1 | L11: 10.5 | M11: 54600 | N11: 13.5 | O11: 70200 | P11: 15600 | Q11: -0.22222222 | R11: 100 | S11: 95 | T11: 100 | U11: 100 | V11: 100 | W11: 98.9 | X11: No | Y11: No | AA11: Preserve
A12: C | B12: Incumbent defense | C12: Atlanta DC | D12: Lot 2 - Roma | E12: Roma Tomato Bulk 25lb | F12: Spring 2026 | G12: Sunbelt Produce | H12: Green Valley Farms | I12: No | J12: 5200 | K12: 1 | L12: 10.5 | M12: 54600 | N12: 13.5 | O12: 70200 | P12: 15600 | Q12: -0.22222222 | R12: 100 | S12: 95 | T12: 100 | U12: 100 | V12: 0 | W12: 78.9 | X12: No | Y12: No | AA12: Create
A13: C | B13: Incumbent defense | C13: Dallas DC | D13: Lot 1 - Grape | E13: Premium Grape Tomato 10oz | F13: Spring 2026 | G13: Green Valley Farms | H13: Green Valley Farms | I13: Yes | J13: 5200 | K13: 1 | L13: 10.5 | M13: 54600 | N13: 13.5 | O13: 70200 | P13: 15600 | Q13: -0.22222222 | R13: 100 | S13: 95 | T13: 100 | U13: 100 | V13: 100 | W13: 98.9 | X13: No | Y13: No | AA13: Preserve
A14: C | B14: Incumbent defense | C14: Dallas DC | D14: Lot 2 - Roma | E14: Roma Tomato Bulk 25lb | F14: Spring 2026 | G14: Sunbelt Produce | H14: Green Valley Farms | I14: No | J14: 5200 | K14: 1 | L14: 10.5 | M14: 54600 | N14: 13.5 | O14: 70200 | P14: 15600 | Q14: -0.22222222 | R14: 100 | S14: 95 | T14: 100 | U14: 100 | V14: 0 | W14: 78.9 | X14: No | Y14: No | AA14: Create
... A30: G | B30: Preferred supplier | C30: Dallas DC | D30: Lot 2 - Roma | E30: Roma Tomato Bulk 25lb | F30: Spring 2026 | G30: Sunbelt Produce | H30: Green Valley Farms | I30: No | J30: 5200 | K30: 1 | L30: 10.5 | M30: 54600 | N30: 13.5 | O30: 70200 | P30: 15600 | Q30: -0.22222222 | R30: 100 | S30: 95 | T30: 100 | U30: 100 | V30: 0 | W30: 78.9 | X30: No | Y30: No | AA30: Create
